<?xml version="1.0"?>
<robot  name="aubo_i5">
  
  <link name="base_footprint">  
  </link>

  <link name="car_base_link">
    <inertial>
      <origin
        xyz="-0.00210927865415705 -0.260107698526606 0.105086427982548"
        rpy="0 0 0" />
      <mass
        value="1.57357225459974" />
      <inertia
        ixx="0.0312577262111476"
        ixy="1.27984469849575E-05"
        ixz="-0.000122382696795917"
        iyy="0.030599900800728"
        iyz="-1.58703768394668E-05"
        izz="0.0499563374651639" />
    </inertial>
    <visual>
      <origin
        xyz="0 0 0"
        rpy="0 0 0" />
      <geometry>
        <mesh
          filename="package://aubo_description/meshes/car/car_base_link.STL" />
      </geometry>
      <material
        name="">
        <color
          rgba="1 1 1 1" />
      </material>
    </visual>
    <collision>
      <origin
        xyz="0 0 0"
        rpy="0 0 0" />
      <geometry>
        <mesh
          filename="package://aubo_description/meshes/car/car_base_link.STL" />
      </geometry>
    </collision>
  </link>

  <joint name="car_base_joint" type="fixed">
    <parent link = "base_footprint" />
    <child link = "car_base_link" />
    <origin xyz="0.0 0.24 0.03" rpy="0.0 0.0 0.0" />
    <axis xyz="0 0 1" />
    <limit lower="0" upper="0" effort="0" velocity="0" />
    <safety_controller k_velocity="0" />
  </joint>

  <link name="car_cube_link">
    <inertial>
      <origin
        xyz="0.358478838747814 0.48993765705809 0.589064189549533"
        rpy="0 0 0" />
      <mass
        value="31.8228891222604" />
      <inertia
        ixx="0.373774052441912"
        ixy="0.000664387306119399"
        ixz="-0.000477035977810397"
        iyy="0.558083842274581"
        iyz="0.000406359279044083"
        izz="0.334149245721581" />
    </inertial>
    <visual>
      <origin
        xyz="0 0 0"
        rpy="0 0 0" />
      <geometry>
        <mesh
          filename="package://aubo_description/meshes/car/car_cube_link.STL" />
      </geometry>
      <material
        name="">
        <color
          rgba="0.529411764705882 0.549019607843137 0.549019607843137 1" />
      </material>
    </visual>
    <collision>
      <origin
        xyz="0 0 0"
        rpy="0 0 0" />
      <geometry>
        <mesh
          filename="package://aubo_description/meshes/car/car_cube_link.STL" />
      </geometry>
    </collision>
  </link>

  <joint name="car_cube_joint" type="fixed">
    <parent link = "base_footprint" />
    <child link = "car_cube_link" />
    <origin xyz="0.35 -0.557 -0.2105" rpy="0.0 0.0 3.1415926" />
    <axis xyz="0 0 1" />
    <limit lower="0" upper="0" effort="0" velocity="0" />
    <safety_controller k_velocity="0" />
  </joint>

  <link name="mynt_camera_link">  
  </link>
 
  <joint name="mynt_camera_joint" type="fixed">
    <origin xyz="0.0 0.027 0.47" rpy="-1.57 -1.57 0" /> 
    <parent link="car_base_link" />
    <child link="mynt_camera_link" />
    <axis xyz="0 0 1" /> 
    <limit
      lower="0"
      upper="0"
      effort="0"
      velocity="0" />
    <safety_controller
      k_velocity="0" />
  </joint>  
 
  <link name="wheel_left_front_Link">
    <inertial>
      <origin
        xyz="0 0 0"
        rpy="0 0 0" />
      <mass
        value="2.17040011885322" />
      <inertia
        ixx="0.00853160339994296"
        ixy="-1.53519798183805E-19"
        ixz="0"
        iyy="0.0157846368685991"
        iyz="1.11093237939281E-19"
        izz="0.00853160339994296" />
    </inertial>
    <visual>
      <origin
        xyz="0 0 0"
        rpy="0 0 0" />
      <geometry>
        <mesh
          filename="package://aubo_description/meshes/car/wheel_left_front_Link.STL" />
      </geometry>
      <material
        name="">
        <color
          rgba="0.294117647058824 0.294117647058824 0.294117647058824 1" />
      </material>
    </visual>
    <collision>
      <origin
        xyz="0 0 0"
        rpy="0 0 0" />
      <geometry>
        <mesh
          filename="package://aubo_description/meshes/car/wheel_left_front_Link.STL" />
      </geometry>
    </collision>
  </link>
  
  <joint name="wheel_left_front_joint" type="fixed">
    <origin
      xyz="0.04 -0.12 -0.313828"
      rpy="0 0 0" />
    <parent
      link="car_base_link" />
    <child
      link="wheel_left_front_Link" />
    <axis
      xyz="0 0 1" />
    <limit
      lower="0"
      upper="0"
      effort="0"
      velocity="0" />
    <safety_controller
      k_velocity="0" />
  </joint>

  <link name="wheel_left_back_link">
    <inertial>
      <origin
        xyz="0 0.0325348107596733 -1.73472347597681E-18"
        rpy="0 0 0" />
      <mass
        value="2.17040011885322" />
      <inertia
        ixx="0.00853160339994296"
        ixy="3.4447933384136E-20"
        ixz="-4.33680868994202E-19"
        iyy="0.0157846368685991"
        iyz="2.49519540830026E-20"
        izz="0.00853160339994296" />
    </inertial>
    <visual>
      <origin
        xyz="0 0 0"
        rpy="0 0 0" />
      <geometry>
        <mesh
          filename="package://aubo_description/meshes/car/wheel_left_back_link.STL" />
      </geometry>
      <material
        name="">
        <color
          rgba="0.294117647058824 0.294117647058824 0.294117647058824 1" />
      </material>
    </visual>
    <collision>
      <origin
        xyz="0 0 0"
        rpy="0 0 0" />
      <geometry>
        <mesh
          filename="package://aubo_description/meshes/car/wheel_left_back_link.STL" />
      </geometry>
    </collision>
  
  </link>
  
  <joint name="wheel_left_back_joint" type="fixed">
    <origin
      xyz="0.04 -0.43 0.044"
      rpy="0 0 0" />
    <parent
      link="car_base_link" />
    <child
      link="wheel_left_back_link" />
    <axis
      xyz="0 0 1" />
    <limit
      lower="0"
      upper="0"
      effort="0"
      velocity="0" />
    <safety_controller
      k_velocity="0" />
  </joint>
  
  <link name="wheel_right_front_link">
    <inertial>
      <origin
        xyz="5.55111512312578E-17 0.0325348107596733 -2.77555756156289E-17"
        rpy="0 0 0" />
      <mass
        value="2.17040011885322" />
      <inertia
        ixx="0.00853160339994297"
        ixy="2.32882617446588E-20"
        ixz="0"
        iyy="0.0157846368685991"
        iyz="5.99338640108921E-20"
        izz="0.00853160339994297" />
    </inertial>
    <visual>
      <origin
        xyz="0 0 0"
        rpy="0 0 0" />
      <geometry>
        <mesh
          filename="package://aubo_description/meshes/car/wheel_right_front_link.STL" />
      </geometry>
      <material
        name="">
        <color
          rgba="0.294117647058824 0.294117647058824 0.294117647058824 1" />
      </material>
    </visual>
    <collision>
      <origin
        xyz="0 0 0"
        rpy="0 0 0" />
      <geometry>
        <mesh
          filename="package://aubo_description/meshes/car/wheel_right_front_link.STL" />
      </geometry>
    </collision>
  </link>
  
  <joint name="wheel_right_front_joint" type="fixed">
    <origin
      xyz="0.9 -0.12 -0.313828"
      rpy="0 0 0" />
    <parent
      link="car_base_link" />
    <child
      link="wheel_right_front_link" />
    <axis
      xyz="0 0 1" />
    <limit
      lower="0"
      upper="0"
      effort="0"
      velocity="0" />
    <safety_controller
      k_velocity="0" />
  </joint>
  
  <link name="wheel_right_back_link">
    <inertial>
      <origin
        xyz="1.73472347597681E-18 0.0325348107596733 -6.93889390390723E-18"
        rpy="0 0 0" />
      <mass
        value="2.17040011885322" />
      <inertia
        ixx="0.00853160339994297"
        ixy="1.86595686490066E-20"
        ixz="-4.33680868994202E-19"
        iyy="0.0157846368685991"
        iyz="1.87018152407058E-21"
        izz="0.00853160339994297" />
    </inertial>
    <visual>
      <origin
        xyz="0 0 0"
        rpy="0 0 0" />
      <geometry>
        <mesh
          filename="package://aubo_description/meshes/car/wheel_right_back_link.STL" />
      </geometry>
      <material
        name="">
        <color
          rgba="0.294117647058824 0.294117647058824 0.294117647058824 1" />
      </material>
    </visual>
    <collision>
      <origin
        xyz="0 0 0"
        rpy="0 0 0" />
      <geometry>
        <mesh
          filename="package://aubo_description/meshes/car/wheel_right_back_link.STL" />
      </geometry>
    </collision>
  </link>
  
  <joint name="wheel_right_back_joint" type="fixed">
    <origin
      xyz="0.9 -0.43 0.044"
      rpy="0 0 0" />
    <parent
      link="car_base_link" />
    <child
      link="wheel_right_back_link" />
    <axis
      xyz="0 0 1" />
    <limit
      lower="0"
      upper="0"
      effort="0"
      velocity="0" />
    <safety_controller
      k_velocity="0" />
  </joint>
   
  <link name="base_link">
    <inertial>
      <origin xyz="-1.4795E-13 0.0015384 0.020951" rpy="0 0 0" />
      <mass value="0.83419" />
      <inertia ixx="0.0014414" ixy="7.8809E-15" ixz="8.5328E-16" iyy="0.0013542" iyz="-1.4364E-05" izz="0.0024659" />
    </inertial>
    <visual>
      <origin xyz="0 0 0" rpy="0 0 0" />
      <geometry>
        <mesh filename="package://aubo_description/meshes/aubo_i5/visual/base_link.DAE" />
      </geometry>
      <material name="">
        <color rgba="1 1 1 1" />
      </material>
    </visual>
    <collision>
      <origin xyz="0 0 0" rpy="0 0 0" />
      <geometry>
        <mesh filename="package://aubo_description/meshes/aubo_i5/collision/base_link.STL" />
      </geometry>
    </collision>
  </link>

  <joint name="base_link_joint" type="fixed">
    <parent link = "base_footprint" />
    <child link = "base_link" />
    <origin xyz="0.0 0.1 0.59" rpy="0.0 0.0 3.14" />
    <axis xyz="0 0 1" />
    <limit lower="-3.05" upper="3.05" effort="0" velocity="0" />
  </joint>

  <link name="shoulder_Link">
    <inertial>
      <origin xyz="3.2508868974735E-07 0.00534955349296065 -0.00883689325611056" rpy="0 0 0" />
      <mass value="1.57658348693929" />
      <inertia ixx="0.0040640448663128" ixy="0" ixz="0" iyy="0.00392863238466817" iyz="-0.000160151642851425" izz="0.0030869857349184" />
    </inertial>
    <visual>
      <origin xyz="0 0 0" rpy="0 0 0" />
      <geometry>
        <mesh filename="package://aubo_description/meshes/aubo_i5/visual/shoulder_Link.DAE" />
      </geometry>
      <material name="">
        <color rgba="1 1 1 1" />
      </material>
    </visual>
    <collision>
      <origin xyz="0 0 0" rpy="0 0 0" />
      <geometry>
        <mesh filename="package://aubo_description/meshes/aubo_i5/collision/shoulder_Link.STL" />
      </geometry>
    </collision>
  </link>

  <joint name="shoulder_joint" type="revolute">
    <origin xyz="0 0 0.122" rpy="0 0 3.1416" />
    <parent link="base_link" />
    <child link="shoulder_Link" />
    <axis xyz="0 0 1" />
    <limit lower="-3.05" upper="3.05" effort="0" velocity="0" />
  </joint>

  <link name="upperArm_Link">
    <inertial>
      <origin xyz="0.203996646979614 2.01304585036544E-10 0.0127641545395984" rpy="0 0 0" />
      <mass value="4.04175782265494" />
      <inertia ixx="0.00965399211106204" ixy="0" ixz="0" iyy="0.144993869035655" iyz="0" izz="0.142607184038966" />
    </inertial>
    <visual>
      <origin xyz="0 0 0" rpy="0 0 0" />
      <geometry>
        <mesh filename="package://aubo_description/meshes/aubo_i5/visual/upperArm_Link.DAE" />
      </geometry>
      <material name="">
        <color rgba="1 1 1 1" />
      </material>
    </visual>
    <collision>
      <origin xyz="0 0 0" rpy="0 0 0" />
      <geometry>
        <mesh filename="package://aubo_description/meshes/aubo_i5/collision/upperArm_Link.STL" />
      </geometry>
    </collision>
  </link>

  <joint name="upperArm_joint" type="revolute">
    <origin xyz="0 0.1215 0" rpy="-1.5708 -1.5708 0" />
    <parent link="shoulder_Link" />
    <child link="upperArm_Link" />
    <axis xyz="0 0 1" />
    <limit lower="-3.05" upper="3.05" effort="0" velocity="0" />
  </joint>

  <link name="foreArm_Link">
    <inertial>
      <origin xyz="0.188922115560337 6.78882434739072E-07 0.0981026740461557" rpy="0 0 0" />
      <mass  value="2.27145669098343" />
      <inertia ixx="0.00214322284946289" ixy="0" ixz="-0.00073120631553383" iyy="0.0443926090878205" iyz="0" izz="0.0441273797128365" />
    </inertial>
    <visual>
      <origin xyz="0 0 0" rpy="0 0 0" />
      <geometry>
        <mesh filename="package://aubo_description/meshes/aubo_i5/visual/foreArm_Link.DAE" />
      </geometry>
      <material name="">
        <color rgba="1 1 1 1" />
      </material>
    </visual>
    <collision>
      <origin xyz="0 0 0" rpy="0 0 0" />
      <geometry>
        <mesh filename="package://aubo_description/meshes/aubo_i5/collision/foreArm_Link.STL" />
      </geometry>
    </collision>
  </link>

  <joint name="foreArm_joint" type="revolute">
    <origin xyz="0.408 0 0" rpy="-3.1416 -5.1632E-18 -5.459E-16" />
    <parent link="upperArm_Link" />
    <child link="foreArm_Link" />
    <axis xyz="0 0 1" />
    <limit lower="-3.05" upper="3.05" effort="0" velocity="0" />
  </joint>

  <link name="wrist1_Link">
    <inertial>
      <origin xyz="7.54205137428592E-07 0.0062481254331257 -0.00392367464072373" rpy="0 0 0" />
      <mass value="0.500477539188764" />
      <inertia ixx="0.00071194605962081" ixy="0" ixz="0" iyy="0.00040588242872958" iyz="-2.30808694377512E-05" izz="0.000685574004861334" />
    </inertial>
    <visual>
      <origin xyz="0 0 0" rpy="0 0 0" />
      <geometry>
        <mesh filename="package://aubo_description/meshes/aubo_i5/visual/wrist1_Link.DAE" />
      </geometry>
      <material name="">
        <color rgba="1 1 1 1" />
      </material>
    </visual>
    <collision>
      <origin xyz="0 0 0" rpy="0 0 0" />
      <geometry>
        <mesh filename="package://aubo_description/meshes/aubo_i5/collision/wrist1_Link.STL" />
      </geometry>
    </collision>
  </link>

  <joint name="wrist1_joint" type="revolute">
    <origin xyz="0.376 0 0" rpy="3.1416 -1.8323E-15 1.5708" />
    <parent link="foreArm_Link" />
    <child link="wrist1_Link" />
    <axis xyz="0 0 1" />
    <limit lower="-3.05" upper="3.05" effort="0" velocity="0" />
  </joint>

  <link name="wrist2_Link">
    <inertial>
      <origin xyz="-7.54207620578635E-07 -0.00624812542617262 -0.00392367464115684" rpy="0 0 0" />
      <mass value="0.500477539245988" />
      <inertia ixx="0.00071194605981829" ixy="0" ixz="0" iyy="0.000405882428755442" iyz="2.30808694515886E-05" izz="0.000685574005112107" />
    </inertial>
    <visual>
      <origin xyz="0 0 0" rpy="0 0 0" />
      <geometry>
        <mesh filename="package://aubo_description/meshes/aubo_i5/visual/wrist2_Link.DAE" />
      </geometry>
      <material name="">
        <color rgba="1 1 1 1" />
      </material>
    </visual>
    <collision>
      <origin xyz="0 0 0" rpy="0 0 0" />
      <geometry>
        <mesh filename="package://aubo_description/meshes/aubo_i5/collision/wrist2_Link.STL" />
      </geometry>
    </collision>
  </link>

  <joint name="wrist2_joint" type="revolute">
    <origin xyz="0 0.1025 0" rpy="-1.5708 -1.8709E-15 -1.6653E-16" />
    <parent link="wrist1_Link" />
    <child link="wrist2_Link" />
    <axis xyz="0 0 1" />
    <limit lower="-3.05" upper="3.05" effort="0" velocity="0" />
  </joint>

  <link name="wrist3_Link">
    <inertial>
      <origin xyz="3.92048778449938E-10 0.000175788057281467 -0.0213294490706684" rpy="0 0 0" />
      <mass value="0.158309554874285" />
      <inertia ixx="7.31376196034769E-05" ixy="0" ixz="0" iyy="7.19528188876563E-05" iyz="0" izz="0.000108772439051422" />
    </inertial>
    <visual>
      <origin xyz="0 0 0" rpy="0 0 0" />
      <geometry>
        <mesh filename="package://aubo_description/meshes/aubo_i5/visual/wrist3_Link.DAE" />
      </geometry>
      <material name="">
        <color rgba="1 1 1 1" />
      </material>
    </visual>
    <collision>
      <origin xyz="0 0 0" rpy="0 0 0" />
      <geometry>
        <mesh filename="package://aubo_description/meshes/aubo_i5/collision/wrist3_Link.STL" />
      </geometry>
    </collision>
  </link>

  <joint name="wrist3_joint" type="revolute">
    <origin xyz="0 -0.094 0" rpy="1.5708 0 1.7907E-15" />
    <parent link="wrist2_Link" />
    <child link="wrist3_Link" />
    <axis xyz="0 0 1" />
    <limit lower="-3.05" upper="3.05" effort="0" velocity="0" />
  </joint>
 
  <link name="kinect2_rgb_optical_frame"> 
  </link>
 <!---0.00471435414308 -0.0894849667007 -0.995928202119 0.0098606198788-->
  <joint name="kinect2_rgb_optical_joint" type="fixed">
    <parent link="wrist3_Link" />
    <child link = "kinect2_rgb_optical_frame" />
    <origin xyz="-0.106744813734 0.092974366887 0.0530513667371" rpy="0.179298499038  0.00762563591405 -3.12110595845" />  
    <axis xyz="0 0 1" /> 
    <limit
      lower="0"
      upper="0"
      effort="0"
      velocity="0" />
    <safety_controller
      k_velocity="0" />
  </joint>

  <link name="kinect_camera_link"> 
    <inertial>
      <origin
        xyz="0 0 0"
        rpy="0 0 0" />
      <mass
        value="2.17040011885322" />
      <inertia
        ixx="0.00853160339994296"
        ixy="-1.53519798183805E-19"
        ixz="0"
        iyy="0.0157846368685991"
        iyz="1.11093237939281E-19"
        izz="0.00853160339994296" />
    </inertial>
   <visual>
     <origin xyz="0 0 0" rpy="0 0 0" />
     <geometry>
       <box size="0.25 0.14 0.07" />
     </geometry>
     <material name="Cyan">
       <color rgba="0 1.0 1.0 1.0"/>
     </material>
   </visual> 
   <collision>
     <origin xyz="0 0 0" rpy="0 0 0"/>
     <geometry>
       <box size="0.25 0.14 0.07" />
     </geometry>
   </collision> 
  </link>
 
  <joint name="kinect_camera_joint" type="fixed">
    <origin xyz="0.0 0.045 0.04" rpy="0 0 0" /> 
    <parent link="wrist3_Link" />
    <child link="kinect_camera_link" />
    <axis xyz="0 0 1" /> 
    <limit
      lower="0"
      upper="0"
      effort="0"
      velocity="0" />
    <safety_controller
      k_velocity="0" />
  </joint>  


  <link name="dh_grasp_link">
    <inertial>
      <origin
        xyz="0 0 0"
        rpy="0 0 0" />
      <mass
        value="2.17040011885322" />
      <inertia
        ixx="0.00853160339994296"
        ixy="-1.53519798183805E-19"
        ixz="0"
        iyy="0.0157846368685991"
        iyz="1.11093237939281E-19"
        izz="0.00853160339994296" />
    </inertial> 
   <visual>
     <origin xyz="0 0 -0.04" rpy="0 0 0" />
     <geometry>
       <box size="0.15 0.05 0.10" />
     </geometry>
     <material name="Cyan">
       <color rgba="0 1.0 1.0 1.0"/>
     </material>
   </visual> 
   <collision>
     <origin xyz="0 0 0" rpy="0 0 0"/>
     <geometry>
       <box size="0.15 0.05 0.15" />
     </geometry>
   </collision> 
  </link>

  <joint name="dh_grasp_joint" type="fixed">
    <origin xyz="-0.02 -0.017 0.185" rpy="0 0 0" /> 
    <parent link="wrist3_Link" />
    <child link="dh_grasp_link" />
    <axis xyz="0 0 1" /> 
    <limit
      lower="0"
      upper="0"
      effort="0"
      velocity="0" />
    <safety_controller
      k_velocity="0" />
  </joint> 
  
</robot>
